2025-08-31 14:57:04,906 ERROR C:\django-project\simple_signup\.venv\Lib\site-packages\django\utils\log.py:253 Internal Server Error: /news/create/
Stack Trace:
None
Traceback (most recent call last):
  File "C:\django-project\simple_signup\.venv\Lib\site-packages\redis\connection.py", line 389, in connect_check_health
    sock = self.retry.call_with_retry(
        lambda: self._connect(), lambda error: self.disconnect(error)
    )
  File "C:\django-project\simple_signup\.venv\Lib\site-packages\redis\retry.py", line 105, in call_with_retry
    return do()
  File "C:\django-project\simple_signup\.venv\Lib\site-packages\redis\connection.py", line 390, in <lambda>
    lambda: self._connect(), lambda error: self.disconnect(error)
            ~~~~~~~~~~~~~^^
  File "C:\django-project\simple_signup\.venv\Lib\site-packages\redis\connection.py", line 803, in _connect
    raise err
  File "C:\django-project\simple_signup\.venv\Lib\site-packages\redis\connection.py", line 787, in _connect
    sock.connect(socket_address)
    ~~~~~~~~~~~~^^^^^^^^^^^^^^^^
ConnectionRefusedError: [WinError 10061] Подключение не установлено, т.к. конечный компьютер отверг запрос на подключение

During handling of the above exception, another exception occurred:

Traceback (most recent call last):
  File "C:\django-project\simple_signup\.venv\Lib\site-packages\celery\backends\redis.py", line 127, in reconnect_on_error
    yield
  File "C:\django-project\simple_signup\.venv\Lib\site-packages\celery\backends\redis.py", line 177, in _consume_from
    self._pubsub.subscribe(key)
    ~~~~~~~~~~~~~~~~~~~~~~^^^^^
  File "C:\django-project\simple_signup\.venv\Lib\site-packages\redis\client.py", line 1030, in subscribe
    ret_val = self.execute_command("SUBSCRIBE", *new_channels.keys())
  File "C:\django-project\simple_signup\.venv\Lib\site-packages\redis\client.py", line 860, in execute_command
    self.connection = self.connection_pool.get_connection()
                      ~~~~~~~~~~~~~~~~~~~~~~~~~~~~~~~~~~~^^
  File "C:\django-project\simple_signup\.venv\Lib\site-packages\redis\utils.py", line 195, in wrapper
    return func(*args, **kwargs)
  File "C:\django-project\simple_signup\.venv\Lib\site-packages\redis\connection.py", line 1533, in get_connection
    connection.connect()
    ~~~~~~~~~~~~~~~~~~^^
  File "C:\django-project\simple_signup\.venv\Lib\site-packages\redis\connection.py", line 380, in connect
    self.connect_check_health(check_health=True)
    ~~~~~~~~~~~~~~~~~~~~~~~~~^^^^^^^^^^^^^^^^^^^
  File "C:\django-project\simple_signup\.venv\Lib\site-packages\redis\connection.py", line 397, in connect_check_health
    raise ConnectionError(self._error_message(e))
redis.exceptions.ConnectionError: Error 10061 connecting to localhost:6379. Подключение не установлено, т.к. конечный компьютер отверг запрос на подключение.

During handling of the above exception, another exception occurred:

Traceback (most recent call last):
  File "C:\django-project\simple_signup\.venv\Lib\site-packages\redis\connection.py", line 389, in connect_check_health
    sock = self.retry.call_with_retry(
        lambda: self._connect(), lambda error: self.disconnect(error)
    )
  File "C:\django-project\simple_signup\.venv\Lib\site-packages\redis\retry.py", line 105, in call_with_retry
    return do()
  File "C:\django-project\simple_signup\.venv\Lib\site-packages\redis\connection.py", line 390, in <lambda>
    lambda: self._connect(), lambda error: self.disconnect(error)
            ~~~~~~~~~~~~~^^
  File "C:\django-project\simple_signup\.venv\Lib\site-packages\redis\connection.py", line 803, in _connect
    raise err
  File "C:\django-project\simple_signup\.venv\Lib\site-packages\redis\connection.py", line 787, in _connect
    sock.connect(socket_address)
    ~~~~~~~~~~~~^^^^^^^^^^^^^^^^
ConnectionRefusedError: [WinError 10061] Подключение не установлено, т.к. конечный компьютер отверг запрос на подключение

During handling of the above exception, another exception occurred:

Traceback (most recent call last):
  File "C:\django-project\simple_signup\.venv\Lib\site-packages\kombu\connection.py", line 472, in _reraise_as_library_errors
    yield
  File "C:\django-project\simple_signup\.venv\Lib\site-packages\celery\app\base.py", line 929, in send_task
    self.backend.on_task_call(P, task_id)
    ~~~~~~~~~~~~~~~~~~~~~~~~~^^^^^^^^^^^^
  File "C:\django-project\simple_signup\.venv\Lib\site-packages\celery\backends\redis.py", line 378, in on_task_call
    self.result_consumer.consume_from(task_id)
    ~~~~~~~~~~~~~~~~~~~~~~~~~~~~~~~~~^^^^^^^^^
  File "C:\django-project\simple_signup\.venv\Lib\site-packages\celery\backends\redis.py", line 169, in consume_from
    return self.start(task_id)
           ~~~~~~~~~~^^^^^^^^^
  File "C:\django-project\simple_signup\.venv\Lib\site-packages\celery\backends\redis.py", line 147, in start
    self._consume_from(initial_task_id)
    ~~~~~~~~~~~~~~~~~~^^^^^^^^^^^^^^^^^
  File "C:\django-project\simple_signup\.venv\Lib\site-packages\celery\backends\redis.py", line 176, in _consume_from
    with self.reconnect_on_error():
         ~~~~~~~~~~~~~~~~~~~~~~~^^
  File "C:\Program Files\Python313\Lib\contextlib.py", line 162, in __exit__
    self.gen.throw(value)
    ~~~~~~~~~~~~~~^^^^^^^
  File "C:\django-project\simple_signup\.venv\Lib\site-packages\celery\backends\redis.py", line 130, in reconnect_on_error
    self._ensure(self._reconnect_pubsub, ())
    ~~~~~~~~~~~~^^^^^^^^^^^^^^^^^^^^^^^^^^^^
  File "C:\django-project\simple_signup\.venv\Lib\site-packages\celery\backends\redis.py", line 389, in ensure
    return retry_over_time(
        fun, self.connection_errors, args, {},
        partial(self.on_connection_error, max_retries),
        **retry_policy)
  File "C:\django-project\simple_signup\.venv\Lib\site-packages\kombu\utils\functional.py", line 318, in retry_over_time
    return fun(*args, **kwargs)
  File "C:\django-project\simple_signup\.venv\Lib\site-packages\celery\backends\redis.py", line 106, in _reconnect_pubsub
    metas = self.backend.client.mget(self.subscribed_to)
  File "C:\django-project\simple_signup\.venv\Lib\site-packages\redis\commands\core.py", line 1994, in mget
    return self.execute_command("MGET", *args, **options)
           ~~~~~~~~~~~~~~~~~~~~^^^^^^^^^^^^^^^^^^^^^^^^^^
  File "C:\django-project\simple_signup\.venv\Lib\site-packages\redis\client.py", line 621, in execute_command
    return self._execute_command(*args, **options)
           ~~~~~~~~~~~~~~~~~~~~~^^^^^^^^^^^^^^^^^^
  File "C:\django-project\simple_signup\.venv\Lib\site-packages\redis\client.py", line 627, in _execute_command
    conn = self.connection or pool.get_connection()
                              ~~~~~~~~~~~~~~~~~~~^^
  File "C:\django-project\simple_signup\.venv\Lib\site-packages\redis\utils.py", line 195, in wrapper
    return func(*args, **kwargs)
  File "C:\django-project\simple_signup\.venv\Lib\site-packages\redis\connection.py", line 1533, in get_connection
    connection.connect()
    ~~~~~~~~~~~~~~~~~~^^
  File "C:\django-project\simple_signup\.venv\Lib\site-packages\redis\connection.py", line 380, in connect
    self.connect_check_health(check_health=True)
    ~~~~~~~~~~~~~~~~~~~~~~~~~^^^^^^^^^^^^^^^^^^^
  File "C:\django-project\simple_signup\.venv\Lib\site-packages\redis\connection.py", line 397, in connect_check_health
    raise ConnectionError(self._error_message(e))
redis.exceptions.ConnectionError: Error 10061 connecting to localhost:6379. Подключение не установлено, т.к. конечный компьютер отверг запрос на подключение.

The above exception was the direct cause of the following exception:

Traceback (most recent call last):
  File "C:\django-project\simple_signup\.venv\Lib\site-packages\django\core\handlers\exception.py", line 55, in inner
    response = get_response(request)
  File "C:\django-project\simple_signup\.venv\Lib\site-packages\django\core\handlers\base.py", line 197, in _get_response
    response = wrapped_callback(request, *callback_args, **callback_kwargs)
  File "C:\django-project\simple_signup\.venv\Lib\site-packages\django\views\generic\base.py", line 105, in view
    return self.dispatch(request, *args, **kwargs)
           ~~~~~~~~~~~~~^^^^^^^^^^^^^^^^^^^^^^^^^^
  File "C:\django-project\simple_signup\.venv\Lib\site-packages\django\contrib\auth\mixins.py", line 109, in dispatch
    return super().dispatch(request, *args, **kwargs)
           ~~~~~~~~~~~~~~~~^^^^^^^^^^^^^^^^^^^^^^^^^^
  File "C:\django-project\simple_signup\.venv\Lib\site-packages\django\views\generic\base.py", line 144, in dispatch
    return handler(request, *args, **kwargs)
  File "C:\django-project\simple_signup\.venv\Lib\site-packages\django\views\generic\edit.py", line 182, in post
    return super().post(request, *args, **kwargs)
           ~~~~~~~~~~~~^^^^^^^^^^^^^^^^^^^^^^^^^^
  File "C:\django-project\simple_signup\.venv\Lib\site-packages\django\views\generic\edit.py", line 151, in post
    return self.form_valid(form)
           ~~~~~~~~~~~~~~~^^^^^^
  File "C:\django-project\newspaper\news\views.py", line 134, in form_valid
    post.category.add(*categories)
    ~~~~~~~~~~~~~~~~~^^^^^^^^^^^^^
  File "C:\django-project\simple_signup\.venv\Lib\site-packages\django\db\models\fields\related_descriptors.py", line 1256, in add
    self._add_items(
    ~~~~~~~~~~~~~~~^
        self.source_field_name,
        ^^^^^^^^^^^^^^^^^^^^^^^
    ...<2 lines>...
        through_defaults=through_defaults,
        ^^^^^^^^^^^^^^^^^^^^^^^^^^^^^^^^^^
    )
    ^
  File "C:\django-project\simple_signup\.venv\Lib\site-packages\django\db\models\fields\related_descriptors.py", line 1566, in _add_items
    signals.m2m_changed.send(
    ~~~~~~~~~~~~~~~~~~~~~~~~^
        sender=self.through,
        ^^^^^^^^^^^^^^^^^^^^
    ...<5 lines>...
        using=db,
        ^^^^^^^^^
    )
    ^
  File "C:\django-project\simple_signup\.venv\Lib\site-packages\django\dispatch\dispatcher.py", line 189, in send
    response = receiver(signal=self, sender=sender, **named)
  File "C:\django-project\newspaper\news\signals.py", line 96, in notify_subscribers_m2m
    send_notification.delay(instance.id)
    ~~~~~~~~~~~~~~~~~~~~~~~^^^^^^^^^^^^^
  File "C:\django-project\simple_signup\.venv\Lib\site-packages\celery\app\task.py", line 444, in delay
    return self.apply_async(args, kwargs)
           ~~~~~~~~~~~~~~~~^^^^^^^^^^^^^^
  File "C:\django-project\simple_signup\.venv\Lib\site-packages\celery\app\task.py", line 601, in apply_async
    return app.send_task(
           ~~~~~~~~~~~~~^
        self.name, args, kwargs, task_id=task_id, producer=producer,
        ^^^^^^^^^^^^^^^^^^^^^^^^^^^^^^^^^^^^^^^^^^^^^^^^^^^^^^^^^^^^
    ...<2 lines>...
        **options
        ^^^^^^^^^
    )
    ^
  File "C:\django-project\simple_signup\.venv\Lib\site-packages\celery\app\base.py", line 927, in send_task
    with P.connection._reraise_as_library_errors():
         ~~~~~~~~~~~~~~~~~~~~~~~~~~~~~~~~~~~~~~~^^
  File "C:\Program Files\Python313\Lib\contextlib.py", line 162, in __exit__
    self.gen.throw(value)
    ~~~~~~~~~~~~~~^^^^^^^
  File "C:\django-project\simple_signup\.venv\Lib\site-packages\kombu\connection.py", line 476, in _reraise_as_library_errors
    raise ConnectionError(str(exc)) from exc
kombu.exceptions.OperationalError: Error 10061 connecting to localhost:6379. Подключение не установлено, т.к. конечный компьютер отверг запрос на подключение.
2025-08-31 14:57:04,918 ERROR C:\django-project\simple_signup\.venv\Lib\site-packages\django\core\servers\basehttp.py:213 "POST /news/create/ HTTP/1.1" 500 330723
Stack Trace:
None
